Workbook

Sheet الإعدادات
B1: ⚙️ إعدادات الحاسبة
B2: أدخل القيم في الخلايا الصفراء — كل الصيغ في باقي الأوراق تتحدث تلقائياً
B4: 🎯 هامش الربح المستهدف (%) | C4: 0.3 | D4: نسبة الربح المطلوبة — يؤثر على أسعار كل المنتجات
B5: ♻️ نسبة الهدر (%) | C5: 0.05 | D5: نسبة الفاقد من المواد الخام (5-10% طبيعي)
B6: 📦 الوحدات المتوقعة شهرياً | C6: 500 | D6: إجمالي كل الطلبات المتوقعة في الشهر
B8: 💡 الخلايا الصفراء هي خلايا الإدخال — باقي الخلايا تُحسب تلقائياً

Sheet لوحة التحكم
B1: 📊 لوحة التحكم — ملخص تكاليف المطعم
B2: 📌 هذه الورقة تُحسب تلقائياً من باقي الأوراق — غيّر هامش الربح في ورقة "الإعدادات" وسترى الأثر هنا وفي التسعير
B4: ⚙️ الإعدادات المفعّلة
B5: هامش الربح المستهدف | C5: ='الإعدادات'!B4
B6: نسبة الهدر | C6: ='الإعدادات'!B5
B7: الوحدات المتوقعة/شهر | C7: ='الإعدادات'!B6
B9: 💰 تفصيل التكاليف
B10: 🏗️ إجمالي المصاريف التأسيسية | C10: =SUM('تأسيسية'!C5:C24)
B11: 📌 إجمالي المصاريف الثابتة/شهر | C11: =SUM('ثابتة'!C5:C24)
B12: ⚙️ إجمالي المصاريف التشغيلية/شهر | C12: =SUM('تشغيلية'!C5:C24)
B13: 📣 إجمالي الدعاية والإعلان/شهر | C13: =SUM('دعاية'!C5:C24)
B14: 📂 مصاريف أخرى شهرية | C14: =SUMIF('أخرى'!D5:D19,"نعم",'أخرى'!C5:C19)
B15: 📂 مصاريف أخرى لمرة واحدة | C15: =SUMIF('أخرى'!D5:D19,"لا",'أخرى'!C5:C19)
B16: 📅 إجمالي المصاريف الشهرية الكلية | C16: =C11+C12+C13+C14
B17: 📈 التكاليف المتغيرة / طلب واحد | C17: ='متغيرة'!G20
B18: 🛵 نسبة % من الإيراد (متغيرة) | C18: ='متغيرة'!G21
B19: ⚖️ توزيع المصاريف الثابتة / وحدة | C19: =IF(الإعدادات!B6>0,C16/الإعدادات!B6,0)
B21: 💎 رأس المال المطلوب
B22: المصاريف التأسيسية | C22: =C10
B23: مصاريف أخرى لمرة واحدة | C23: =C15
B24: احتياطي تشغيل (3 أشهر) | C24: =C16*3
B25: 💰 رأس المال الكلي المقدر | C25: =C22+C23+C24
G27: نوع التكلفة | H27: المبلغ
G28: مصاريف ثابتة | H28: =C11
G29: مصاريف تشغيلية | H29: =C12
G30: دعاية وإعلان | H30: =C13
G31: مصاريف أخرى | H31: =C14

Sheet تأسيسية
B1: 🏗️ المصاريف التأسيسية
B2: تكاليف تُدفع مرة واحدة عند التأسيس (لا تتكرر)
B4: البند / الوصف | C4: المبلغ (ر.س)
B5: تجهيز وتصميم المطبخ | C5: 0
B6: الأثاث والديكور | C6: 0
B7: الأجهزة والمعدات | C7: 0
B8: رسوم الترخيص والسجل التجاري | C8: 0
B9: تجهيز نظام نقاط البيع (POS) | C9: 0
B10: مخزون أولي للمواد الخام | C10: 0
B11: صيانة وتجهيز المبنى | C11: 0
C12: 0
C13: 0
C14: 0
C15: 0
C16: 0
C17: 0
C18: 0
C19: 0
C20: 0
C21: 0
C22: 0
C23: 0
C24: 0
B25: الإجمالي | C25: =SUM(C5:C24)

Sheet تشغيلية
B1: ⚙️ المصاريف التشغيلية
B2: تكاليف شهرية متكررة تتعلق بتشغيل المطعم
B4: البند / الوصف | C4: المبلغ (ر.س) | D4: ملاحظات
B5: الكهرباء والمياه | C5: 0
B6: الصيانة الدورية | C6: 0
B7: الاشتراكات والبرمجيات | C7: 0
B8: تجديد المواد الاستهلاكية | C8: 0
B9: نفقات متنوعة | C9: 0
C10: 0
C11: 0
C12: 0
C13: 0
C14: 0
C15: 0
C16: 0
C17: 0
C18: 0
C19: 0
C20: 0
C21: 0
... C24: 0
B25: المجموع الشهري | C25: =SUM(C5:C24)

Sheet ثابتة
B1: 📌 المصاريف الثابتة
B2: لا تتغير بتغير المبيعات: إيجار، رواتب، أقساط
B4: البند / الوصف | C4: المبلغ (ر.س) | D4: ملاحظات
B5: الإيجار الشهري | C5: 0
B6: رواتب الموظفين | C6: 0
B7: رواتب الإدارة | C7: 0
B8: التأمينات الاجتماعية | C8: 0
B9: قسط قرض أو تمويل | C9: 0
B10: رسوم ثابتة أخرى | C10: 0
C11: 0
C12: 0
C13: 0
C14: 0
C15: 0
C16: 0
C17: 0
C18: 0
C19: 0
C20: 0
C21: 0
C22: 0
... C24: 0
B25: المجموع الشهري | C25: =SUM(C5:C24)

Sheet متغيرة
B1: 📈 التكاليف المتغيرة
B2: تكاليف تتغير مع حجم الطلبات — كل بند يؤثر مباشرة على الحد الأدنى لسعر البيع. نوع الحساب: "لكل طلب" أو "لكل X طلب" أو "% من الإيراد"
B4: البند | C4: نوع الحساب | D4: التكلفة / المبلغ | E4: لكل X طلب | F4: % من الإيراد | G4: التكلفة/وحدة
B5: تغليف وأكياس | C5: لكل طلب | D5: 0 | E5: 1 | F5: 0 | G5: =IF(C5="لكل طلب",D5,IF(C5="لكل X طلب",IF(E5>0,D5/E5,0),0))
B6: أدوات أكل ومناديل | C6: لكل طلب | D6: 0 | E6: 1 | F6: 0 | G6: =IF(C6="لكل طلب",D6,IF(C6="لكل X طلب",IF(E6>0,D6/E6,0),0))
B7: غاز الطبخ | C7: لكل X طلب | D7: 0 | E7: 10 | F7: 0 | G7: =IF(C7="لكل طلب",D7,IF(C7="لكل X طلب",IF(E7>0,D7/E7,0),0))
B8: كهرباء متغيرة | C8: لكل X طلب | D8: 0 | E8: 50 | F8: 0 | G8: =IF(C8="لكل طلب",D8,IF(C8="لكل X طلب",IF(E8>0,D8/E8,0),0))
B9: صيانة متغيرة | C9: لكل X طلب | D9: 0 | E9: 100 | F9: 0 | G9: =IF(C9="لكل طلب",D9,IF(C9="لكل X طلب",IF(E9>0,D9/E9,0),0))
B10: عمولة منصة توصيل | C10: % من الإيراد | D10: 0 | E10: 1 | F10: 0 | G10: =IF(C10="لكل طلب",D10,IF(C10="لكل X طلب",IF(E10>0,D10/E10,0),0))
C11: لكل طلب | D11: 0 | E11: 1 | F11: 0 | G11: =IF(C11="لكل طلب",D11,IF(C11="لكل X طلب",IF(E11>0,D11/E11,0),0))
C12: لكل طلب | D12: 0 | E12: 1 | F12: 0 | G12: =IF(C12="لكل طلب",D12,IF(C12="لكل X طلب",IF(E12>0,D12/E12,0),0))
C13: لكل طلب | D13: 0 | E13: 1 | F13: 0 | G13: =IF(C13="لكل طلب",D13,IF(C13="لكل X طلب",IF(E13>0,D13/E13,0),0))
C14: لكل طلب | D14: 0 | E14: 1 | F14: 0 | G14: =IF(C14="لكل طلب",D14,IF(C14="لكل X طلب",IF(E14>0,D14/E14,0),0))
C15: لكل طلب | D15: 0 | E15: 1 | F15: 0 | G15: =IF(C15="لكل طلب",D15,IF(C15="لكل X طلب",IF(E15>0,D15/E15,0),0))
C16: لكل طلب | D16: 0 | E16: 1 | F16: 0 | G16: =IF(C16="لكل طلب",D16,IF(C16="لكل X طلب",IF(E16>0,D16/E16,0),0))
C17: لكل طلب | D17: 0 | E17: 1 | F17: 0 | G17: =IF(C17="لكل طلب",D17,IF(C17="لكل X طلب",IF(E17>0,D17/E17,0),0))
C18: لكل طلب | D18: 0 | E18: 1 | F18: 0 | G18: =IF(C18="لكل طلب",D18,IF(C18="لكل X طلب",IF(E18>0,D18/E18,0),0))
C19: لكل طلب | D19: 0 | E19: 1 | F19: 0 | G19: =IF(C19="لكل طلب",D19,IF(C19="لكل X طلب",IF(E19>0,D19/E19,0),0))
B20: إجمالي التكلفة المتغيرة / طلب | G20: =SUM(G5:G19)
B21: إجمالي نسبة % من الإيراد | G21: =SUMIF(C5:C19,"% من الإيراد",F5:F19)

Sheet دعاية
B1: 📣 مصاريف الدعاية والإعلان
B2: إعلانات، محتوى، سوشيال ميديا، عروض
B4: البند / الوصف | C4: المبلغ (ر.س) | D4: ملاحظات
B5: إدارة وسائل التواصل الاجتماعي | C5: 0
B6: إعلانات مدفوعة (Meta / Google) | C6: 0
B7: تصوير وإنتاج محتوى | C7: 0
B8: عروض وخصومات ترويجية | C8: 0
C9: 0
C10: 0
C11: 0
C12: 0
C13: 0
C14: 0
C15: 0
C16: 0
C17: 0
C18: 0
C19: 0
C20: 0
... C24: 0
B25: المجموع الشهري | C25: =SUM(C5:C24)

Sheet أخرى
B1: 📂 مصاريف أخرى
B2: أي بنود إضافية — اكتب "نعم" في عمود شهري؟ لتُحتسب ضمن المصاريف الشهرية
B4: البند | C4: المبلغ (ر.س) | D4: شهري؟ | E4: ملاحظات
C5: 0 | D5: لا
C6: 0 | D6: لا
C7: 0 | D7: لا
C8: 0 | D8: لا
C9: 0 | D9: لا
C10: 0 | D10: لا
C11: 0 | D11: لا
C12: 0 | D12: لا
C13: 0 | D13: لا
C14: 0 | D14: لا
C15: 0 | D15: لا
C16: 0 | D16: لا
... C19: 0 | D19: لا
B20: إجمالي الشهري | C20: =SUMIF(D5:D19,"نعم",C5:C19)
B21: إجمالي لمرة واحدة | C21: =SUMIF(D5:D19,"لا",C5:C19)

Sheet تسعير المنتجات
B1: 💰 تسعير المنتجات — الحد الأدنى للسعر يُحسب تلقائياً
B2: 📌 الخلايا الصفراء للإدخال — الخلايا الزرقاء محسوبة تلقائياً — السعر الأخضر = صحيح | الأحمر = منخفض جداً
B3: 🍽️ المنتج 1
B4: اسم المنتج | C4: منتج 1 | D4: وحدات/شهر | E4: 100
B5: 🧂 المكونات والمواد الخام
B6: المكوّن | C6: سعر الوحدة (ر.س) | D6: الكمية | E6: التكلفة الإجمالية | F6: ملاحظات
C7: 0 | D7: 0 | E7: =C7*D7
C8: 0 | D8: 0 | E8: =C8*D8
C9: 0 | D9: 0 | E9: =C9*D9
C10: 0 | D10: 0 | E10: =C10*D10
C11: 0 | D11: 0 | E11: =C11*D11
C12: 0 | D12: 0 | E12: =C12*D12
C13: 0 | D13: 0 | E13: =C13*D13
C14: 0 | D14: 0 | E14: =C14*D14
B15: 📊 تفصيل التكلفة والسعر
B16: تكلفة المواد الخام | C16: =SUM(E7:E14) | D16: مجموع تكلفة المكونات
B17: بعد الهدر | C17: =C16*(1+الإعدادات!$B$5) | D17: ="+ "&TEXT(الإعدادات!$B$5,"0.0%")&" هدر — زيادة: "&TEXT(C17-C16,"#,##0.00")&" ر.س"
B18: توزيع المصاريف الثابتة | C18: ='لوحة التحكم'!$C$19 | D18: ="من إجمالي "&TEXT(لوحة_التحكم!$C$16,"#,##0.00 ر.س")&" ÷ "&TEXT(الإعدادات!$B$6,"#,##0")&" وحدة"
B19: التكاليف المتغيرة / طلب | C19: ='لوحة التحكم'!$C$17 | D19: تغليف + غاز + صيانة + ...
B20: إجمالي التكلفة / وحدة | C20: =C17+C18+C19
B21: ="الحد الأدنى للسعر (هامش "&TEXT(الإعدادات!$B$4,"0%")&")" | C21: =IF((1-الإعدادات!$B$4-لوحة_التحكم!$C$18)>0,C20/(1-الإعدادات!$B$4-لوحة_التحكم!$C$18),0) | D21: ="تكلفة "&TEXT(C20,"#,##0.00")&" ر.س ÷ (1 - هامش - عمولة)"
B22: سعر البيع المقترح (أدخله) | C22: 0 | D22: ← أدخل سعر البيع الذي تريد تحديده
B23: حالة السعر | C23: =IF(C22=0,"أدخل السعر أولاً",IF(C22>=C21,"✅ السعر صحيح",IF(C22>=C21*0.9,"⚠️ السعر قريب - راجع","🚨 السعر منخفض جداً"))) | D23: =IF(C22>0,"الحد الأدنى: "&TEXT(C21,"#,##0.00")&" ر.س","")
B24: هامش الربح الفعلي % | C24: =IF(C22>0,(C22-(C20+لوحة_التحكم!$C$18*C22))/C22,0)
B25: نقطة التعادل (وحدة/شهر) | C25: =IF(AND(C21>0,(C21-(C17+C19))>0),CEILING(لوحة_التحكم!$C$16/(C21-(C17+C19)),1),0)
B28: 🍽️ المنتج 2
B29: اسم المنتج | C29: منتج 2 | D29: وحدات/شهر | E29: 100
B30: 🧂 المكونات والمواد الخام
B31: المكوّن | C31: سعر الوحدة (ر.س) | D31: الكمية | E31: التكلفة الإجمالية | F31: ملاحظات
C32: 0 | D32: 0 | E32: =C32*D32
C33: 0 | D33: 0 | E33: =C33*D33
C34: 0 | D34: 0 | E34: =C34*D34
C35: 0 | D35: 0 | E35: =C35*D35
C36: 0 | D36: 0 | E36: =C36*D36
C37: 0 | D37: 0 | E37: =C37*D37
C38: 0 | D38: 0 | E38: =C38*D38
C39: 0 | D39: 0 | E39: =C39*D39
B40: 📊 تفصيل التكلفة والسعر
B41: تكلفة المواد الخام | C41: =SUM(E32:E39) | D41: مجموع تكلفة المكونات
B42: بعد الهدر | C42: =C41*(1+الإعدادات!$B$5) | D42: ="+ "&TEXT(الإعدادات!$B$5,"0.0%")&" هدر — زيادة: "&TEXT(C42-C41,"#,##0.00")&" ر.س"
...
